Workbook

Sheet Model
B1: 2016 | C1: =B1+1 -> 2017 | D1: =C1+1 -> 2018 | E1: =D1+1 -> 2019 | F1: =E1+1 -> 2020 | G1: =F1+1 -> 2021 | H1: =G1+1 -> 2022 | I1: =H1+1 -> 2023 | J1: =I1+1 -> 2024 | ... P1: =O1+1 -> 2030
A2: Revenue
A3: Gross Revenue from operations | B3: 30700.88 | C3: 30958.19 | D3: 33100.94 | E3: 33972.23 | F3: 28836.09 | G3: 30959.19 | H3: 29245.47 | I3: 33805.65 | J3: 37455.72 | K3: =(K98*K119)/(10^6) -> 50593.039 | L3: =(L98*L119)/(10^6) -> 60930.328 | M3: =(M98*M119)/(10^6) -> 73387.317 | N3: =(N98*N119)/(10^6) -> 88400.027 | O3: =(O98*O119)/(10^6) -> 106494.41 | P3: =(P98*P119)/(10^6) -> 128304.94
A4: Other Income | B4: 422.43 | C4: 521.95 | D4: 523.17 | E4: 691.25 | F4: 778.34 | G4: 557.9 | H4: 556.91 | I4: 565.16 | J4: 892.55 | K4: =J4+(J4*2%) -> 910.401 | L4: =K4+(K4*2%) -> 928.60902 | M4: =L4+(L4*2%) -> 947.1812 | N4: =M4+(M4*2%) -> 966.12482 | O4: =N4+(N4*2%) -> 985.44732 | P4: =O4+(O4*2%) -> 1005.1563
A6: Total Revenue | B6: =SUM(B3:B4) -> 31123.31 | C6: =SUM(C3:C4) -> 31480.14 | D6: =SUM(D3:D4) -> 33624.11 | E6: =SUM(E3:E4) -> 34663.48 | F6: =SUM(F3:F4) -> 29614.43 | G6: =SUM(G3:G4) -> 31517.09 | H6: =SUM(H3:H4) -> 29802.38 | I6: =SUM(I3:I4) -> 34370.81 | ... P6: =SUM(P3:P4) -> 129310.1
A8: Costs
A9: Raw Materials | B9: 19321.72 | C9: 18993.87 | D9: 21995.94 | E9: 23346.1 | F9: 19867.19 | G9: 21968.04 | H9: 20708.07 | I9: 24019.73 | J9: 24767.46 | K9: =$K$3*K124 -> 34123.554 | L9: =$L$3*L124 -> 41917.674 | M9: =$M$3*M124 -> 51497.346 | N9: =$N$3*N124 -> 63272.705 | O9: =$O$3*O124 -> 77748.315 | P9: =$P$3*P124 -> 95544.949
A10: Purchases | B10: 0 | C10: 0 | D10: 0 | E10: 0 | F10: 0 | G10: 31.14 | H10: 45.95 | I10: 47.43 | J10: 484.2 | K10: =$K$3*K125 -> 667.11019 | L10: =$L$3*L125 -> 819.48403 | M10: =$M$3*M125 -> 1006.7651 | N10: =$N$3*N125 -> 1236.9716 | O10: =$O$3*O125 -> 1519.9675 | P10: =$P$3*P125 -> 1867.8889
A11: Changes in Stock in Trade | B11: -11.88 | C11: 96.74 | D11: -110.12 | E11: -28.38 | F11: -169.78 | G11: -255.57 | H11: 72.71 | I11: -209.04 | J11: 179.11 | K11: =$K$3*K126 -> 246.77015 | L11: =$L$3*L126 -> 303.13462 | M11: =$M$3*M126 -> 372.41161 | N11: =$N$3*N126 -> 457.56708 | O11: =$O$3*O126 -> 562.24985 | P11: =$P$3*P126 -> 690.94917
A12: Employee Cost | B12: 1315.93 | C12: 1432.49 | D12: 1583.71 | E12: 1730.24 | F12: 1841.7 | G12: 1951.02 | H12: 1935.44 | I12: 2189.83 | J12: 2402.34 | K12: =$K$3*K127 -> 3309.842 | L12: =$L$3*L127 -> 4065.839 | M12: =$M$3*M127 -> 4995.0271 | N12: =$N$3*N127 -> 6137.1877 | O12: =$O$3*O127 -> 7541.2612 | P12: =$P$3*P127 -> 9267.4603
A13: Other Expenses | B13: 3361.96 | C13: 3485.89 | D13: 3663.79 | E13: 3672.49 | F13: 3339.02 | G13: 3165.05 | H13: 3114.53 | I13: 3771.47 | J13: 4366.9 | K13: =$K$3*K128 -> 6016.5293 | L13: =$L$3*L128 -> 7390.7575 | M13: =$M$3*M128 -> 9079.8071 | N13: =$N$3*N128 -> 11155.992 | O13: =$O$3*O128 -> 13708.273 | P13: =$P$3*P128 -> 16846.105
A14: Excise Duty | B14: 2258.18 | C14: 2371.13 | D14: 642.57 | E14: 1.41 | F14: 1.35 | G14: 2.91 | H14: 13.16 | I14: 9.43 | J14: 3.19 | K14: =$K$3*K129 -> 4.3950465 | L14: =$L$3*L129 -> 5.3989138 | M14: =$M$3*M129 -> 6.6327566 | N14: =$N$3*N129 -> 8.1493997 | O14: =$O$3*O129 -> 10.01383 | P14: =$P$3*P129 -> 12.306001
A16: Total Costs | B16: =SUM(B9:B14) -> 26245.91 | C16: =SUM(C9:C14) -> 26380.12 | D16: =SUM(D9:D14) -> 27775.89 | E16: =SUM(E9:E14) -> 28721.86 | F16: =SUM(F9:F14) -> 24879.48 | G16: =SUM(G9:G14) -> 26862.59 | H16: =SUM(H9:H14) -> 25889.86 | I16: =SUM(I9:I14) -> 29828.85 | ... P16: =SUM(P9:P14) -> 124229.66
A18: Operating Profits | B18: =B6-B16 -> 4877.4 | C18: =C6-C16 -> 5100.02 | D18: =D6-D16 -> 5848.22 | E18: =E6-E16 -> 5941.62 | F18: =F6-F16 -> 4734.95 | G18: =G6-G16 -> 4654.5 | H18: =H6-H16 -> 3912.52 | I18: =I6-I16 -> 4541.96 | ... P18: =P6-P16 -> 5080.4388
A20: Depreciation & Amortization | B20: 437.64 | C20: 492.73 | D20: 574.98 | E20: 624.44 | F20: 845.76 | G20: 715.12 | H20: 689.52 | I20: 697.39 | J20: 711.41 | K20: =K204 -> 862.99014 | L20: =L204 -> 895.40809 | M20: =M204 -> 931.06783 | N20: =N204 -> 970.29354 | O20: =O204 -> 1013.4418 | P20: =P204 -> 1060.9049
A22: EBIT | B22: =B18-B20 -> 4439.76 | C22: =C18-C20 -> 4607.29 | D22: =D18-D20 -> 5273.24 | E22: =E18-E20 -> 5317.18 | F22: =F18-F20 -> 3889.19 | G22: =G18-G20 -> 3939.38 | H22: =H18-H20 -> 3223 | I22: =I18-I20 -> 3844.57 | ... P22: =P18-P20 -> 4019.5338
A24: Interest | B24: 4.89 | C24: 6.05 | D24: 6.25 | E24: 8.6 | F24: 22.02 | G24: 21.84 | H24: 25.8 | I24: 19.87 | J24: 18.5 | K24: 20 | L24: 20 | M24: 20 | N24: 20 | O24: 20 | P24: 20
A26: Profit Before Exceptional Items and Taxes | B26: =B22-B24 -> 4434.87 | C26: =C22-C24 -> 4601.24 | D26: =D22-D24 -> 5266.99 | E26: =E22-E24 -> 5308.58 | F26: =F22-F24 -> 3867.17 | G26: =G22-G24 -> 3917.54 | H26: =H22-H24 -> 3197.2 | I26: =I22-I24 -> 3824.7 | ... P26: =P22-P24 -> 3999.5338
A27: Other/Exceptional Items | B27: 0 | C27: ='Notes and Assumptions'!D3 -> 50 | D27: ='Notes and Assumptions'!E3 -> 55 | E27: ='Notes and Assumptions'!F3 -> 60.5 | F27: ='Notes and Assumptions'!G3 -> 66.55 | G27: ='Notes and Assumptions'!H3 -> 73.205 | H27: ='Notes and Assumptions'!I3 -> 80.5255 | I27: ='Notes and Assumptions'!J3 -> 88.57805 | J27: -160 | K27: 80 | L27: 80 | M27: 80 | N27: 80 | O27: 80 | P27: 80
A28: Profit Before Taxes | B28: =SUM(B26:B27) -> 4434.87 | C28: =SUM(C26:C27) -> 4651.24 | D28: =SUM(D26:D27) -> 5321.99 | E28: =SUM(E26:E27) -> 5369.08 | F28: =SUM(F26:F27) -> 3933.72 | G28: =SUM(G26:G27) -> 3990.745 | H28: =SUM(H26:H27) -> 3277.7255 | I28: =SUM(I26:I27) -> 3913.2781 | ... P28: =SUM(P26:P27) -> 4079.5338
A30: Taxes | B30: 1274.68 | C30: 1281.34 | D30: 1546.8 | E30: 1625.86 | F30: 940.43 | G30: 913.27 | H30: 729.06 | I30: 963.98 | J30: 1290.4 | K30: =K28*K31 -> 1899.6747 | L30: =L28*L31 -> 1956.3721 | M30: =M28*M31 -> 1951.6323 | N30: =N28*N31 -> 1856.1856 | O30: =O28*O31 -> 1630.8999 | P30: =P28*P31 -> 1223.8602
A31: Tax Rate | K31: 0.3 | L31: 0.3 | M31: 0.3 | N31: 0.3 | O31: 0.3 | P31: 0.3
A32: Profit Before Minority Interest and Share in Associates | B32: =B28-B30 -> 3160.19 | C32: =C28-C30 -> 3369.9 | D32: =D28-D30 -> 3775.19 | E32: =E28-E30 -> 3743.22 | F32: =F28-F30 -> 2993.29 | G32: =G28-G30 -> 3077.475 | H32: =H28-H30 -> 2548.6655 | I32: =I28-I30 -> 2949.2981 | ... P32: =P28-P30 -> 2855.6737
A36: Profit for the Year | B36: =B32+B33 -> 3160.19 | C36: =C32+C33 -> 3369.9 | D36: =D32+D33 -> 3775.19 | E36: =E32+E33 -> 3743.22 | F36: =F32+F33 -> 2993.29 | G36: =G32+G33 -> 3077.475 | H36: =H32+H33 -> 2548.6655 | I36: =I32+I33 -> 2949.2981 | ... P36: =P32+P33 -> 2855.6737
A39: Sources of Funds
A41: Shareholder Funds
A42: Share Capital | B42: 39.94 | C42: 39.94 | D42: 39.94 | E42: 39.94 | F42: 39.95 | G42: 39.96 | H42: 39.96 | I42: 39.97 | J42: 39.98 | K42: 39.98 | L42: 39.98 | M42: 39.98 | N42: 39.98 | O42: 39.98 | P42: 39.98
A43: Reserves & Surplus | B43: 8794.47 | C43: 10071.35 | D43: 11728.94 | E43: 12817.17 | F43: 14096.45 | G43: 15158 | H43: 15806.69 | I43: 16665.12 | J43: 17946.2 | K43: =J43*102% -> 18305.124 | L43: =K43*102% -> 18671.226 | M43: =L43*102% -> 19044.651 | N43: =M43*102% -> 19425.544 | O43: =N43*102% -> 19814.055 | P43: =O43*102% -> 20210.336
A44: Total Equity | B44: =SUM(B42:B43) -> 8834.41 | C44: =SUM(C42:C43) -> 10111.29 | D44: =SUM(D42:D43) -> 11768.88 | E44: =SUM(E42:E43) -> 12857.11 | F44: =SUM(F42:F43) -> 14136.4 | G44: =SUM(G42:G43) -> 15197.96 | H44: =SUM(H42:H43) -> 15846.65 | I44: =SUM(I42:I43) -> 16705.09 | ... P44: =SUM(P42:P43) -> 20250.316
A49: Long Term Liabilities | B49: =SUM(B50:B53) -> 290.13 | C49: =SUM(C50:C53) -> 489.64 | D49: =SUM(D50:D53) -> 626.6 | E49: =SUM(E50:E53) -> 653.71 | F49: =SUM(F50:F53) -> 636.87 | G49: =SUM(G50:G53) -> 852.4 | H49: =SUM(H50:H53) -> 798.43 | I49: =SUM(I50:I53) -> 934.07 | ... P49: =SUM(P50:P53) -> 1231.0705
A50: Lease/Loans | B50: 0 | C50: 0 | D50: 0 | E50: 0 | F50: 121.67 | G50: 129.81 | H50: 142.32 | I50: 134.29 | J50: 111.5 | K50: =J50*102% -> 113.73 | L50: =K50*103% -> 117.1419 | M50: =L50*103% -> 120.65616 | N50: =M50*103% -> 124.27584 | O50: =N50*103% -> 128.00412 | P50: =O50*103% -> 131.84424
A51: Other Long Term Liabilities | B51: 0 | C51: 0 | D51: 0 | E51: 0 | F51: 0 | G51: 146.04 | H51: 155.04 | I51: 196.29 | J51: 178.13 | K51: =J51*102% -> 181.6926 | L51: =K51*103% -> 187.14338 | M51: =L51*103% -> 192.75768 | N51: =M51*103% -> 198.54041 | O51: =N51*103% -> 204.49662 | P51: =O51*103% -> 210.63152
A52: Long Term Provisions | B52: 67.6 | C52: 75.3 | D52: 114.94 | E52: 117.2 | F52: 122.37 | G52: 172.46 | H52: 178.07 | I52: 198.12 | J52: 316.66 | K52: =J52*102% -> 322.9932 | L52: =K52*103% -> 332.683 | M52: =L52*103% -> 342.66349 | N52: =M52*103% -> 352.94339 | O52: =N52*103% -> 363.53169 | P52: =O52*103% -> 374.43764
A53: Deferred Tax Liabilities | B53: 222.53 | C53: 414.34 | D53: 511.66 | E53: 536.51 | F53: 392.83 | G53: 404.09 | H53: 323 | I53: 405.37 | J53: 434.82 | K53: =J53*102% -> 443.5164 | L53: =K53*103% -> 456.82189 | M53: =L53*103% -> 470.52655 | N53: =M53*103% -> 484.64235 | O53: =N53*103% -> 499.18162 | P53: =O53*103% -> 514.15706
A55: Current Liabilities | B55: =SUM(B57:B61) -> 3448.32 | C55: =SUM(C57:C61) -> 4093.33 | D55: =SUM(D57:D61) -> 4343.32 | E55: =SUM(E57:E61) -> 4130.36 | F55: =SUM(F57:F61) -> 3976.06 | G55: =SUM(G57:G61) -> 6110.22 | H55: =SUM(H57:H61) -> 5072.38 | I55: =SUM(I57:I61) -> 5623.98 | ... P55: =SUM(P57:P61) -> 21683.535
A57: Short Term Borrowings | B57: 0 | C57: 0 | D57: 0 | E57: 0 | F57: 28.29 | G57: 19.7 | H57: 25.75 | I57: 22.02 | J57: 26.08 | K57: =K163 -> 556.52343 | L57: =L163 -> 670.2336 | M57: =M163 -> 807.26049 | N57: =N163 -> 972.40029 | O57: =O163 -> 1171.4385 | P57: =P163 -> 1411.3544
A58: Trade Payables | B58: 2650.56 | C58: 3247.27 | D58: 3318.81 | E58: 3355.28 | F58: =8.33+3022.18 -> 3030.51 | G58: =15.71+5188.9 -> 5204.61 | H58: =25.55+4234.79 -> 4260.34 | I58: =1.15+4703.31 -> 4704.46 | J58: =15.79+5512.36 -> 5528.15 | K58: =K164 -> 6071.1647 | L58: =L164 -> 7311.6393 | M58: =M164 -> 8806.4781 | N58: =N164 -> 10608.003 | O58: =O164 -> 12779.329 | P58: =P164 -> 15396.593
A59: Other Current Liabilities | B59: 502.4 | C59: 454.28 | D59: 762.58 | E59: 495.18 | F59: 518.26 | G59: 566.01 | H59: 492.12 | I59: 557.84 | J59: 585.6 | K59: =K165 -> 758.89559 | L59: =L165 -> 913.95491 | M59: =M165 -> 1100.8098 | N59: =N165 -> 1326.0004 | O59: =O165 -> 1597.4161 | P59: =P165 -> 1924.5741
A60: Short Term Provisions | B60: 29.66 | C60: 39.01 | D60: 59.79 | E60: 59.03 | F60: 146.56 | G60: 160.37 | H60: 160.42 | I60: 175.69 | J60: 154.14 | K60: =K166 -> 505.93039 | L60: =L166 -> 609.30328 | M60: =M166 -> 733.87317 | N60: =N166 -> 884.00027 | O60: =O166 -> 1064.9441 | P60: =P166 -> 1283.0494
A61: Other Finance Liabilities | B61: 265.7 | C61: 352.77 | D61: 202.14 | E61: 220.87 | F61: 252.44 | G61: 159.53 | H61: 133.75 | I61: 163.97 | J61: 250.29 | K61: =K167 -> 657.70951 | L61: =L167 -> 792.09426 | M61: =M167 -> 954.03512 | N61: =N167 -> 1149.2003 | O61: =O167 -> 1384.4273 | P61: =P167 -> 1667.9642
...

Sheet Notes and Assumptions
B1: Assumptions | C1: 2016 | D1: 2017 | E1: 2018 | F1: 2019 | G1: 2020 | H1: 2021 | I1: 2022 | J1: 2023 | K1: 2024
B3: =Model!A27 -> Other/Exceptional Items | C3: 0 | D3: 50 | E3: =D3+(D3*10%) -> 55 | F3: =E3+(E3*10%) -> 60.5 | G3: =F3+(F3*10%) -> 66.55 | H3: =G3+(G3*10%) -> 73.205 | I3: =H3+(H3*10%) -> 80.5255 | J3: =I3+(I3*10%) -> 88.57805
B5: Assumptions | C5: 2025 | D5: 2026 | E5: 2027 | F5: 2028 | G5: 2029 | H5: 2030
B6: New capacity increased by 10% | C6: =Model!K94 -> 198000 | D6: =Model!L94 -> 217800 | E6: =Model!M94 -> 239580 | F6: =Model!N94 -> 263538 | G6: =Model!O94 -> 289891.8 | H6: =Model!P94 -> 318880.98
B7: Assets per Car Capacity increased by 10% | C7: =Model!K198 -> 1240.3561 | D7: =Model!L198 -> 1240.3561 | E7: =Model!M198 -> 1240.3561 | F7: =Model!N198 -> 1240.3561 | G7: =Model!O198 -> 1240.3561 | H7: =Model!P198 -> 1240.3561
B8: Growth in domestic market | C8: 0.08 | D8: 0.08 | E8: 0.08 | F8: 0.08 | G8: 0.08 | H8: 0.08
B9: Growth in Exports | C9: 0.05 | D9: 0.05 | E9: 0.05 | F9: 0.05 | G9: 0.05 | H9: 0.05
B10: Overall market share | C10: =Model!K116 -> 0.3 | D10: =Model!L116 -> 0.3 | E10: =Model!M116 -> 0.3 | F10: =Model!N116 -> 0.3 | G10: =Model!O116 -> 0.3 | H10: =Model!P116 -> 0.3
B11: Market share growth | C11: =Model!K120 -> 0.12 | D11: =Model!L120 -> 0.12 | E11: =Model!M120 -> 0.12 | F11: =Model!N120 -> 0.12 | G11: =Model!O120 -> 0.12 | H11: =Model!P120 -> 0.12
B12: Raw Materials | C12: 0.67447133 | D12: 0.68796075 | E12: 0.70171997 | F12: 0.71575437 | G12: 0.73006946 | H12: 0.74467085
B13: Purchases | C13: 0.01318581 | D13: 0.013449526 | E13: 0.013718517 | F13: 0.013992887 | G13: 0.014272745 | H13: 0.014558199
B14: Changes in Stock in Trade | C14: 0.0048775514 | D14: 0.0049751024 | E14: 0.0050746045 | F14: 0.0051760966 | G14: 0.0052796185 | H14: 0.0053852109
B15: Employee Cost | C15: 0.065420897 | D15: 0.066729315 | E15: 0.068063901 | F15: 0.069425179 | G15: 0.070813683 | H15: 0.072229957
B16: Other Expenses | C16: 0.1189201 | D16: 0.1212985 | E16: 0.12372447 | F16: 0.12619896 | G16: 0.12872294 | H16: 0.1312974
B17: Vehicles or Dies for Own Usage | C17: 8.6870577e-05 | D17: 8.8607988e-05 | E17: 9.0380148e-05 | F17: 9.2187751e-05 | G17: 9.4031506e-05 | H17: 9.5912136e-05
B18: Other income increased by 2% | C18: =Model!K4 -> 910.401 | D18: =Model!L4 -> 928.60902 | E18: =Model!M4 -> 947.1812 | F18: =Model!N4 -> 966.12482 | G18: =Model!O4 -> 985.44732 | H18: =Model!P4 -> 1005.1563
B19: Depreciation as % of LY Net Fixed Assets | C19: =Model!K205 -> 0.12 | D19: =Model!L205 -> 0.12 | E19: =Model!M205 -> 0.12 | F19: =Model!N205 -> 0.12 | G19: =Model!O205 -> 0.12 | H19: =Model!P205 -> 0.12
B20: Interest | C20: =Model!K24 -> 20 | D20: =Model!L24 -> 20 | E20: =Model!M24 -> 20 | F20: =Model!N24 -> 20 | G20: =Model!O24 -> 20 | H20: =Model!P24 -> 20
B21: Other/Exceptional Items | C21: =Model!K27 -> 80 | D21: =Model!L27 -> 80 | E21: =Model!M27 -> 80 | F21: =Model!N27 -> 80 | G21: =Model!O27 -> 80 | H21: =Model!P27 -> 80
B22: Tax Rate | C22: 0.3 | D22: 0.3 | E22: 0.3 | F22: 0.3 | G22: 0.3 | H22: 0.3
B23: Reserves & Surplus increased by 2% | C23: =Model!K43 -> 18305.124 | D23: =Model!L43 -> 18671.226 | E23: =Model!M43 -> 19044.651 | F23: =Model!N43 -> 19425.544 | G23: =Model!O43 -> 19814.055 | H23: =Model!P43 -> 20210.336
B24: Long Term Liabilities values increased by 2% | C24: =Model!K49 -> 1061.9322 | D24: =Model!L49 -> 1093.7902 | E24: =Model!M49 -> 1126.6039 | F24: =Model!N49 -> 1160.402 | G24: =Model!O49 -> 1195.214 | H24: =Model!P49 -> 1231.0705
B25: Long Term Assets increased by 5% | C25: =Model!K67 -> 13251.878 | D25: =Model!L67 -> 11169.811 | E25: =Model!M67 -> 9447.3265 | F25: =Model!N67 -> 8018.1912 | G25: =Model!O67 -> 6828.8499 | H25: =Model!P67 -> 5835.9472
B26: Cash & Bank Balances increased by 5% | C26: =Model!K84 -> 639.3765 | D26: =Model!L84 -> 671.34533 | E26: =Model!M84 -> 704.91259 | F26: =Model!N84 -> 740.15822 | G26: =Model!O84 -> 777.16613 | H26: =Model!P84 -> 816.02444

Sheet Q1
D2: 1. Company & Industry Overview Brief on Hero MotoCorp Hero MotoCorp is the largest two-wheeler manufacturer in India based in India, which was formerly a joint venture of Hero Cycles and the Honda Motor Company of Japan. The alliance was terminated in 2011 after Honda disposed of its 26% share to the Munjal family and the company changed its name to Hero MotoCorp in July 2011. Market Position: Hero MotoCorp company has one of the largest shares in India two-wheeler market standing at about 30% and continues to be the dominant motorcycle manufacturer in India. Key Products: Hero Splendor and Hero HF Deluxe are the best sellers which have contributed 40% of all sales. Karizma XMR, H-D X440 (Harley-Davidson cooperation) and MAVRICK 440 belong to the premium segment with the contribution of about 25% of revenue. Xtreme and Maestro series are also in the company. Revenue Sources: Hero MotoCorp has made a revenue of INR 37,455.72 Crores in the year 2024. The Indian domestic market has contributed 95% of the total revenues, motorcycles being the main business and expanding the export to Africa and Latin America. Industry Trends & Market Dynamics In 2024-25, the market of the two-wheeler in India hit 19.6 million units, with a growth rate of 9.1% per year. By 2025, the market size is projected to be 31.59 billion with a growth of 2.4% CAGR and by 2030 will be 34.74 billion. Competitive Landscape: The industry is relatively concentrated as the five leading companies have a market share of 87.94%. Hero MotoCorp had a market share of 35% in November 2024 followed by Honda with 25%, TVS with 16%, and Bajaj with 11.63%. Honda has gained a lot in FY25, and its share has grown to 25.37% compared to 23.36%, whereas Hero has gone down to 28.84% from 30.79%. Growth Drivers: Electric cars are on spectacular expansion with an estimated growth rate of 21% in the period of 2024 to 2029. Electric two-wheelers had a market of 960,000 units in 2024, and is projected to expand at a CAGR of 28.5% to 11.1 million units by 2033. Regulatory Trends: Starting April 1, 2020, BS6 emission norms became mandatory, as they were obliged to have onboard diagnostics and stricter control of pollution. BS6 fuel has 5 times lower sulphur concentration and NOx is less by 70% in diesel and 25 percent in petrol engines.
